Workbook

Sheet Sheet1
A1: emission_gerbido | B1: emission_PAIP | C1: emission_piacenza | D1: emission_silla2 | E1: el_price_itNord | F1: normalized_heat_demand_milan | G1: co2_concentration_PAIP
A2: 71.499055 | B2: 25.805581 | C2: 14.145926 | D2: 94.978697 | E2: 107.09 | F2: 0.82816823 | G2: =concentration_calc!J2/100 -> 0.08033982
A3: 73.351179 | B3: 25.608278 | C3: 14.070599 | D3: 94.586829 | E3: 104 | F3: 0.83148866 | G3: =concentration_calc!J3/100 -> 0.07980791
A4: 73.237023 | B4: 25.412023 | C4: 14.052147 | D4: 92.841398 | E4: 100 | F4: 0.82512452 | G4: =concentration_calc!J4/100 -> 0.079345383
A5: 75.181515 | B5: 25.635506 | C5: 13.911463 | D5: 92.296493 | E5: 85.66 | F5: 0.81267294 | G5: =concentration_calc!J5/100 -> 0.079998215
A6: 73.501968 | B6: 25.461868 | C6: 14.01258 | D6: 91.914812 | E6: 85 | F6: 0.80492529 | G6: =concentration_calc!J6/100 -> 0.079064543
A7: 75.045564 | B7: 25.662338 | C7: 14.601183 | D7: 92.388821 | E7: 85.53 | F7: 0.81405645 | G7: =concentration_calc!J7/100 -> 0.079209179
A8: 74.404085 | B8: 25.337075 | C8: 14.847291 | D8: 92.167915 | E8: 95.07 | F8: 0.84061981 | G8: =concentration_calc!J8/100 -> 0.078647624
A9: 76.000524 | B9: 24.696386 | C9: 15.16779 | D9: 91.869885 | E9: 104.07 | F9: 0.8547316 | G9: =concentration_calc!J9/100 -> 0.078048768
A10: 75.251895 | B10: 25.474641 | C10: 14.900678 | D10: 90.92625 | E10: 106.95 | F10: 0.85113448 | G10: =concentration_calc!J10/100 -> 0.078476668
A11: 72.283571 | B11: 25.807002 | C11: 14.44794 | D11: 90.750188 | E11: 107.08 | F11: 0.82844494 | G11: =concentration_calc!J11/100 -> 0.079172706
A12: 73.805168 | B12: 25.502799 | C12: 13.559731 | D12: 86.649495 | E12: 104 | F12: 0.79330382 | G12: =concentration_calc!J12/100 -> 0.078164265
A13: 75.145988 | B13: 23.402894 | C13: 13.788638 | D13: 87.557605 | E13: 98.13 | F13: 0.75982291 | G13: =concentration_calc!J13/100 -> 0.07299088
... A8761: 80.700102 | B8761: 26.963862 | C8761: 9.3780954 | D8761: 90.822922 | E8761: 134.32 | F8761: 0.63254012 | G8761: =concentration_calc!J8761/100 -> 0.087097913

Sheet concentration_calc
A1: L1 | C1: L1_corrected | D1: L2 | F1: L2_corrected | H1: Nm3/h (wet) L1 | I1: Nm3/h (wet) L2 | J1: Weighed av. Concentration
A2: 8.017578 | B2: =IF(A2<3,1,0) -> 0 | C2: 8.017578 | D2: 8.049899 | E2: =IF(D2<3,1,0) -> 0 | F2: 8.049899 | H2: 80561.51 | I2: 83026.24 | J2: =(C2*H2+F2*I2)/(H2+I2) -> 8.033982 | K2: =IF(J2<3,1,0) -> 0
A3: 7.907681 | B3: =IF(A3<3,1,0) -> 0 | C3: 7.907681 | D3: 8.053431 | E3: =IF(D3<3,1,0) -> 0 | F3: 8.053431 | H3: 81445.97 | I3: 81972.99 | J3: =(C3*H3+F3*I3)/(H3+I3) -> 7.980791 | K3: =IF(J3<3,1,0) -> 0
A4: 7.932166 | B4: =IF(A4<3,1,0) -> 0 | C4: 7.932166 | D4: 7.936838 | E4: =IF(D4<3,1,0) -> 0 | F4: 7.936838 | H4: 80288.664 | I4: 82823.21 | J4: =(C4*H4+F4*I4)/(H4+I4) -> 7.9345383 | K4: =IF(J4<3,1,0) -> 0
A5: 8.00547 | B5: =IF(A5<3,1,0) -> 0 | C5: 8.00547 | D5: 7.994339 | E5: =IF(D5<3,1,0) -> 0 | F5: 7.994339 | H5: 80384.85 | I5: 82818.695 | J5: =(C5*H5+F5*I5)/(H5+I5) -> 7.9998215 | K5: =IF(J5<3,1,0) -> 0
A6: 7.8371596 | B6: =IF(A6<3,1,0) -> 0 | C6: 7.8371596 | D6: 7.97523 | E6: =IF(D6<3,1,0) -> 0 | F6: 7.97523 | H6: 81697.96 | I6: 82314.37 | J6: =(C6*H6+F6*I6)/(H6+I6) -> 7.9064543 | K6: =IF(J6<3,1,0) -> 0
A7: 7.868458 | B7: =IF(A7<3,1,0) -> 0 | C7: 7.868458 | D7: 7.97307 | E7: =IF(D7<3,1,0) -> 0 | F7: 7.97307 | H7: 82258.13 | I7: 82743.68 | J7: =(C7*H7+F7*I7)/(H7+I7) -> 7.9209179 | K7: =IF(J7<3,1,0) -> 0
A8: 7.8109117 | B8: =IF(A8<3,1,0) -> 0 | C8: 7.8109117 | D8: 7.9178295 | E8: =IF(D8<3,1,0) -> 0 | F8: 7.9178295 | H8: 81435.62 | I8: 82638.04 | J8: =(C8*H8+F8*I8)/(H8+I8) -> 7.8647624 | K8: =IF(J8<3,1,0) -> 0
A9: 7.687413 | B9: =IF(A9<3,1,0) -> 0 | C9: 7.687413 | D9: 7.91702 | E9: =IF(D9<3,1,0) -> 0 | F9: 7.91702 | H9: 78708.8 | I9: 82443.07 | J9: =(C9*H9+F9*I9)/(H9+I9) -> 7.8048768 | K9: =IF(J9<3,1,0) -> 0
A10: 7.798397 | B10: =IF(A10<3,1,0) -> 0 | C10: 7.798397 | D10: 7.897472 | E10: =IF(D10<3,1,0) -> 0 | F10: 7.897472 | H10: 83108.695 | I10: 82215.16 | J10: =(C10*H10+F10*I10)/(H10+I10) -> 7.8476668 | K10: =IF(J10<3,1,0) -> 0
A11: 7.9010615 | B11: =IF(A11<3,1,0) -> 0 | C11: 7.9010615 | D11: 7.9337754 | E11: =IF(D11<3,1,0) -> 0 | F11: 7.9337754 | H11: 83754.72 | I11: 82253.68 | J11: =(C11*H11+F11*I11)/(H11+I11) -> 7.9172706 | K11: =IF(J11<3,1,0) -> 0
A12: 7.930766 | B12: =IF(A12<3,1,0) -> 0 | C12: 7.930766 | D12: 7.699691 | E12: =IF(D12<3,1,0) -> 0 | F12: 7.699691 | H12: 83945.5 | I12: 82222.58 | J12: =(C12*H12+F12*I12)/(H12+I12) -> 7.8164265 | K12: =IF(J12<3,1,0) -> 0
A13: 7.454116 | B13: =IF(A13<3,1,0) -> 0 | C13: 7.454116 | D13: 7.1479807 | E13: =IF(D13<3,1,0) -> 0 | F13: 7.1479807 | H13: 80601.08 | I13: 82692.445 | J13: =(C13*H13+F13*I13)/(H13+I13) -> 7.299088 | K13: =IF(J13<3,1,0) -> 0
... A831: 7.1513996 | B831: =IF(A831<3,1,0) -> 0 | C831: 7.1513996 | D831: 8.432867 | E831: =IF(D831<3,1,0) -> 0 | F831: 8.432867 | H831: 87546.64 | I831: 76540.22 | J831: =(C831*H831+F831*I831)/(H831+I831) -> 7.7491549 | K831: =IF(J831<3,1,0) -> 0
A832: -26.629475 | B832: =IF(A832<3,1,0) -> 1 | C832: =(C831+C833)/2 -> 7.0937268 | D832: 8.645332 | E832: =IF(D832<3,1,0) -> 0 | F832: 8.645332 | H832: 87009.97 | I832: 73518.85 | J832: =(C832*H832+F832*I832)/(H832+I832) -> 7.8043296 | K832: =IF(J832<3,1,0) -> 0
A833: 7.036054 | B833: =IF(A833<3,1,0) -> 0 | C833: 7.036054 | D833: 8.556535 | E833: =IF(D833<3,1,0) -> 0 | F833: 8.556535 | H833: 87214.805 | I833: 76671.84 | J833: =(C833*H833+F833*I833)/(H833+I833) -> 7.7473876 | K833: =IF(J833<3,1,0) -> 0
A834: 7.0561137 | B834: =IF(A834<3,1,0) -> 0 | C834: 7.0561137 | D834: 7.8171506 | E834: =IF(D834<3,1,0) -> 0 | F834: 7.8171506 | H834: 78883.44 | I834: 72209.09 | J834: =(C834*H834+F834*I834)/(H834+I834) -> 7.4198232 | K834: =IF(J834<3,1,0) -> 0
A835: 6.9081664 | B835: =IF(A835<3,1,0) -> 0 | C835: 6.9081664 | D835: 8.330102 | E835: =IF(D835<3,1,0) -> 0 | F835: 8.330102 | H835: 84501.695 | I835: 70830.18 | J835: =(C835*H835+F835*I835)/(H835+I835) -> 7.5565585 | K835: =IF(J835<3,1,0) -> 0
A836: 5.630198 | B836: =IF(A836<3,1,0) -> 0 | C836: 5.630198 | D836: 8.055616 | E836: =IF(D836<3,1,0) -> 0 | F836: 8.055616 | H836: 64155.594 | I836: 78958.54 | J836: =(C836*H836+F836*I836)/(H836+I836) -> 6.968343 | K836: =IF(J836<3,1,0) -> 0
A837: 6.6304593 | B837: =IF(A837<3,1,0) -> 0 | C837: 6.6304593 | D837: 7.670085 | E837: =IF(D837<3,1,0) -> 0 | F837: 7.670085 | H837: 53980.758 | I837: 84916.43 | J837: =(C837*H837+F837*I837)/(H837+I837) -> 7.2660467 | K837: =IF(J837<3,1,0) -> 0
A838: 6.8172174 | B838: =IF(A838<3,1,0) -> 0 | C838: 6.8172174 | D838: 8.227067 | E838: =IF(D838<3,1,0) -> 0 | F838: 8.227067 | H838: 65622.78 | I838: 83550.13 | J838: =(C838*H838+F838*I838)/(H838+I838) -> 7.6068589 | K838: =IF(J838<3,1,0) -> 0
A839: 7.0685053 | B839: =IF(A839<3,1,0) -> 0 | C839: 7.0685053 | D839: 8.353475 | E839: =IF(D839<3,1,0) -> 0 | F839: 8.353475 | H839: 79244.84 | I839: 81517.7 | J839: =(C839*H839+F839*I839)/(H839+I839) -> 7.7200736 | K839: =IF(J839<3,1,0) -> 0
A840: 6.9376364 | B840: =IF(A840<3,1,0) -> 0 | C840: 6.9376364 | D840: 8.50643 | E840: =IF(D840<3,1,0) -> 0 | F840: 8.50643 | H840: 81641.67 | I840: 82907.7 | J840: =(C840*H840+F840*I840)/(H840+I840) -> 7.7280683 | K840: =IF(J840<3,1,0) -> 0
A841: 6.9194965 | B841: =IF(A841<3,1,0) -> 0 | C841: 6.9194965 | D841: 8.457304 | E841: =IF(D841<3,1,0) -> 0 | F841: 8.457304 | H841: 82435.67 | I841: 82100.68 | J841: =(C841*H841+F841*I841)/(H841+I841) -> 7.6868348 | K841: =IF(J841<3,1,0) -> 0
A842: 6.9958134 | B842: =IF(A842<3,1,0) -> 0 | C842: 6.9958134 | D842: 8.171966 | E842: =IF(D842<3,1,0) -> 0 | F842: 8.171966 | H842: 80798.52 | I842: 78701.38 | J842: =(C842*H842+F842*I842)/(H842+I842) -> 7.5761575 | K842: =IF(J842<3,1,0) -> 0
A843: 7.1284037 | B843: =IF(A843<3,1,0) -> 0 | C843: 7.1284037 | D843: 8.513764 | E843: =IF(D843<3,1,0) -> 0 | F843: 8.513764 | H843: 81364.93 | I843: 82829.41 | J843: =(C843*H843+F843*I843)/(H843+I843) -> 7.827262 | K843: =IF(J843<3,1,0) -> 0
A844: 7.0430346 | B844: =IF(A844<3,1,0) -> 0 | C844: 7.0430346 | D844: 8.525964 | E844: =IF(D844<3,1,0) -> 0 | F844: 8.525964 | H844: 82115.1 | I844: 81179.836 | J844: =(C844*H844+F844*I844)/(H844+I844) -> 7.7802526 | K844: =IF(J844<3,1,0) -> 0
... A1324: 6.3139195 | B1324: =IF(A1324<3,1,0) -> 0 | C1324: 6.3139195 | D1324: 8.613911 | E1324: =IF(D1324<3,1,0) -> 0 | F1324: 8.613911 | H1324: 70789.66 | I1324: 79060.39 | J1324: =(C1324*H1324+F1324*I1324)/(H1324+I1324) -> 7.5273874 | K1324: =IF(J1324<3,1,0) -> 0
A1325: 4.5881996 | B1325: =IF(A1325<3,1,0) -> 0 | C1325: =($C$1324+$C$1329)/2 -> 6.2898778 | D1325: 8.319404 | E1325: =IF(D1325<3,1,0) -> 0 | F1325: 8.319404 | H1325: 71889.87 | I1325: 78959.82 | J1325: =(C1325*H1325+F1325*I1325)/(H1325+I1325) -> 7.3522003 | K1325: =IF(J1325<3,1,0) -> 0
A1326: 2.9152122 | B1326: =IF(A1326<3,1,0) -> 1 | C1326: =($C$1324+$C$1329)/2 -> 6.2898778 | D1326: 8.655093 | E1326: =IF(D1326<3,1,0) -> 0 | F1326: 8.655093 | H1326: 72868.56 | I1326: 79953.61 | J1326: =(C1326*H1326+F1326*I1326)/(H1326+I1326) -> 7.5273128 | K1326: =IF(J1326<3,1,0) -> 0
A1327: 2.97423 | B1327: =IF(A1327<3,1,0) -> 1 | C1327: =($C$1324+$C$1329)/2 -> 6.2898778 | D1327: 8.288454 | E1327: =IF(D1327<3,1,0) -> 0 | F1327: 8.288454 | H1327: 57288.527 | I1327: 78481.89 | J1327: =(C1327*H1327+F1327*I1327)/(H1327+I1327) -> 7.4451519 | K1327: =IF(J1327<3,1,0) -> 0
A1328: 4.0824804 | B1328: =IF(A1328<3,1,0) -> 0 | C1328: =($C$1324+$C$1329)/2 -> 6.2898778 | D1328: 8.54482 | E1328: =IF(D1328<3,1,0) -> 0 | F1328: 8.54482 | H1328: 53962.2 | I1328: 79176.734 | J1328: =(C1328*H1328+F1328*I1328)/(H1328+I1328) -> 7.6308752 | K1328: =IF(J1328<3,1,0) -> 0
A1329: 6.2658362 | B1329: =IF(A1329<3,1,0) -> 0 | C1329: 6.2658362 | D1329: 8.648057 | E1329: =IF(D1329<3,1,0) -> 0 | F1329: 8.648057 | H1329: 62908.688 | I1329: 79401.414 | J1329: =(C1329*H1329+F1329*I1329)/(H1329+I1329) -> 7.5949878 | K1329: =IF(J1329<3,1,0) -> 0
A1330: 7.039604 | B1330: =IF(A1330<3,1,0) -> 0 | C1330: 7.039604 | D1330: 8.556468 | E1330: =IF(D1330<3,1,0) -> 0 | F1330: 8.556468 | H1330: 77057.05 | I1330: 80618.86 | J1330: =(C1330*H1330+F1330*I1330)/(H1330+I1330) -> 7.8151686 | K1330: =IF(J1330<3,1,0) -> 0
A1331: 6.981969 | B1331: =IF(A1331<3,1,0) -> 0 | C1331: 6.981969 | D1331: 8.413291 | E1331: =IF(D1331<3,1,0) -> 0 | F1331: 8.413291 | H1331: 80468.09 | I1331: 79959.72 | J1331: =(C1331*H1331+F1331*I1331)/(H1331+I1331) -> 7.6953622 | K1331: =IF(J1331<3,1,0) -> 0
A1332: 7.114776 | B1332: =IF(A1332<3,1,0) -> 0 | C1332: 7.114776 | D1332: 8.4929495 | E1332: =IF(D1332<3,1,0) -> 0 | F1332: 8.4929495 | H1332: 82264.52 | I1332: 78578.805 | J1332: =(C1332*H1332+F1332*I1332)/(H1332+I1332) -> 7.7880724 | K1332: =IF(J1332<3,1,0) -> 0
A1333: 7.2309437 | B1333: =IF(A1333<3,1,0) -> 0 | C1333: 7.2309437 | D1333: 8.425325 | E1333: =IF(D1333<3,1,0) -> 0 | F1333: 8.425325 | H1333: 86469.21 | I1333: 79057.91 | J1333: =(C1333*H1333+F1333*I1333)/(H1333+I1333) -> 7.8013958 | K1333: =IF(J1333<3,1,0) -> 0
A1334: 7.2370515 | B1334: =IF(A1334<3,1,0) -> 0 | C1334: 7.2370515 | D1334: 8.5878525 | E1334: =IF(D1334<3,1,0) -> 0 | F1334: 8.5878525 | H1334: 90571.11 | I1334: 77574.71 | J1334: =(C1334*H1334+F1334*I1334)/(H1334+I1334) -> 7.8602487 | K1334: =IF(J1334<3,1,0) -> 0
A1335: 7.163517 | B1335: =IF(A1335<3,1,0) -> 0 | C1335: 7.163517 | D1335: 8.299511 | E1335: =IF(D1335<3,1,0) -> 0 | F1335: 8.299511 | H1335: 92295.86 | I1335: 76031.97 | J1335: =(C1335*H1335+F1335*I1335)/(H1335+I1335) -> 7.6766339 | K1335: =IF(J1335<3,1,0) -> 0
A1336: 7.2286534 | B1336: =IF(A1336<3,1,0) -> 0 | C1336: 7.2286534 | D1336: 8.540287 | E1336: =IF(D1336<3,1,0) -> 0 | F1336: 8.540287 | H1336: 90038.47 | I1336: 76187.555 | J1336: =(C1336*H1336+F1336*I1336)/(H1336+I1336) -> 7.8298237 | K1336: =IF(J1336<3,1,0) -> 0
...
