Workbook

Sheet capex_oxyfuel
A1: size_tclinker_per_h | B1: capex_eur
A2: 0 | B2: 0
A3: 75 | B3: 50760000
A4: 125 | B4: 72350000
A5: 220 | B5: =_xlfn.FORECAST.LINEAR($A$5, B3:B4, $A$3:$A$4) -> 113371000

Sheet capex_mea
A1: size_tco2out_per_h | B1: capex_eur
A2: 0 | B2: 0
A3: =calculations!D19 -> 4.4302473 | B3: =calculations!D20 -> 13962332
A4: =calculations!G19 -> 14.767491 | B4: =calculations!G20 -> 25360000 | C4: =B4/A4 -> 1717285.6
A5: =calculations!G6 -> 24.418823 | B5: =calculations!G7 -> 26820000
A6: 50 | B6: =_xlfn.FORECAST.LINEAR($A$6, B4:B5, $A$4:$A$5) -> 30689778

Sheet capex_cpu_oxyfuel
A1: size_tco2out_per_h | B1: liquid | C1: gas | D1: supercritical
A2: 0 | B2: 0 | C2: 0 | D2: 0
A3: 75 | B3: 48600000 | C3: 50200000 | D3: 61000000
A4: 125 | B4: 62500000 | C4: 63300000 | D4: 71600000
A5: 220 | B5: =_xlfn.FORECAST.LINEAR($A$5, B3:B4, $A$3:$A$4) -> 88910000 | C5: =_xlfn.FORECAST.LINEAR($A$5, C3:C4, $A$3:$A$4) -> 88190000 | D5: =_xlfn.FORECAST.LINEAR($A$5, D3:D4, $A$3:$A$4) -> 91740000

Sheet capex_compressor_mea
A1: size_tco2out_per_h | B1: liquid | C1: gas | D1: supercritical
A2: 0 | B2: 0 | C2: 0 | D2: 0
A3: =calculations!D19 -> 4.4302473 | B3: 7530000 | C3: =8.00649089380739*10^6 -> 8006490.9 | D3: =10.684945673991*10^6 -> 10684946
A4: =calculations!G19 -> 14.767491 | B4: =11.2041255209316*10^6 -> 11204126 | C4: =12.5665678479893*10^6 -> 12566568 | D4: =16.5887397694844*10^6 -> 16588740
A5: =calculations!G6 -> 24.418823 | B5: =13.2435084663724*10^6 -> 13243508 | C5: =15.1282369696705*10^6 -> 15128237 | D5: =19.9398066221897*10^6 -> 19939807
A6: 50 | B6: =_xlfn.FORECAST.LINEAR($A$6, B4:B5, A4:A5) -> 18648961 | C6: =_xlfn.FORECAST.LINEAR($A$6, C4:C5, A4:A5) -> 21918026 | D6: =_xlfn.FORECAST.LINEAR($A$6, D4:D5, A4:A5) -> 28821921

Sheet energy_oxy_mea
B1: value
A2: beta_oxy | B2: =calculations!C39 -> 0.31280885
A3: alpha_oxy | B3: =calculations!C40 -> 0.078335633
A4: alpha_mea | B4: =calculations!C41 -> 0.038587339
A5: el_recovery_oxy | B5: =calculations!C38 -> 0.10637013

Sheet energy_cpu_compressor
A1: electricity_cons_MWh/tCO2 | B1: liquid | C1: gas | D1: supercritical
A2: el_cons_cpu | B2: 0.17050594 | C2: 0.12024503 | D2: 0.13739153
A3: el_cons_compressor | B3: 0.11930298 | C3: 0.074589552 | D3: 0.089737129

Sheet calculations
A1: CEMCAP ref. plant 3000 tpd of clinker production - 0,85 MtCO2/y | O1: CEMCAP ref. plant 3000 tpd of clinker production - 0,85 MtCO2/y () - high CO2
A2: CAPEX [M€] | C2: CO2 removal rate (direct emissions) | O2: No CCS | P2: P.Oxy only | Q2: MEA 30% - 95%CCR | R2: MEA 50% - 95%CCR | S2: MEA 80% - 95%CCR | T2: MEA 100% - 95%CCR
C3: P.Oxy only | D3: MEA 30% - 95%CCR | E3: MEA 50% - 95%CCR | F3: MEA 80% - 95%CCR | G3: MEA 100% - 95%CCR | N3: Clinker production, tpd | O3: 3000.0035 | P3: 2999.9194 | Q3: 2999.9194 | R3: 2999.9194 | S3: 2999.9194 | T3: 2999.9194
C4: 72.35 | D4: 84.320989 | E4: 89.206549 | F4: 95.44559 | G4: 99.17 | N4: CO2 basic cement plant, kg/s | O4: 29.839568 | P4: - | Q4: - | R4: - | S4: - | T4: -
L5: =1-P6/P5 -> 0.78184912 | N5: CO2 p.oxy cement plant, kg/s | O5: - | P5: 32.665832 | Q5: 32.665832 | R5: 32.665832 | S5: 32.665832 | T5: 32.665832
B6: MEA capacity t/h CO2 out | C6: 0 | D6: =Q7*3600/1000 -> 7.325647 | E6: =R7*3600/1000 -> 12.209412 | F6: =S7*3600/1000 -> 19.535059 | G6: =T7*3600/1000 -> 24.418823 | N6: CO2 emission | O6: 29.839568 | P6: 7.1260802 | Q6: 5.0911782 | R6: 3.734577 | S6: 1.699675 | T6: 0.34307372
B7: CAPEX in EUR | D7: =(D4-$C$4)*10^6 -> 11970989 | E7: =(E4-$C$4)*10^6 -> 16856549 | F7: =(F4-$C$4)*10^6 -> 23095590 | G7: =(G4-$C$4)*10^6 -> 26820000 | N7: CO2 capture by MEA, kg/s | O7: - | P7: 0 | Q7: 2.0349019 | R7: 3.3915032 | S7: 5.4264052 | T7: 6.7830065
B8: specific capex eur/(t_out/h) | D8: =D7/D6 -> 1634120.3 | E8: =E7/E6 -> 1380619.3 | F8: =F7/F6 -> 1182263.7 | G8: =G7/G6 -> 1098333 | N8: Total CO2 captured, kg/s | O8: - | P8: 25.539752 | Q8: 27.574654 | R8: 28.931255 | S8: 30.966157 | T8: 32.322758
B9: specific capex Meur/(t_out/h) | D9: =D8/10^6 -> 1.6341203 | E9: =E8/10^6 -> 1.3806193 | F9: =F8/10^6 -> 1.1822637 | G9: =G8/10^6 -> 1.098333 | N9: Direct CO2 avoided, kg/s | O9: 0 | P9: 22.713488 | Q9: 24.74839 | R9: 26.104991 | S9: 28.139893 | T9: 29.496495
B10: fixed OPEX Meur | C10: 11.9 | D10: 12.12 | E10: 12.22 | F10: 12.4 | G10: 12.51 | K10: =P5*3600/1000/125 -> 0.94077596 | N10: Actual direct CO2 avoided, kg/s | O10: - | P10: 19.887224 | Q10: 21.922126 | R10: 23.278728 | S10: 25.31363 | T10: 26.670231
B11: fixed OPEX MEA Meur | C11: =C10-$C$10 -> 0 | D11: =D10-$C$10 -> 0.22 | E11: =E10-$C$10 -> 0.32 | F11: =F10-$C$10 -> 0.5 | G11: =G10-$C$10 -> 0.61 | N11: CO2 avoidance rate (direct emission) | O11: 0 | P11: 0.76118689 | Q11: 0.82938164 | R11: 0.87484481 | S11: 0.94303956 | T11: 0.98850273
B12: fixed OPEX Fraction of capex | C12: =C10/C4 -> 0.16447823 | D12: =D11*10^6/D7 -> 0.018377764 | E12: =E11*10^6/E7 -> 0.018983719 | F12: =F11*10^6/F7 -> 0.021649154 | G12: =G11*10^6/G7 -> 0.022744221 | N12: kgfuel/s | O12: 4.0947408 | P12: 5.1419804 | Q12: 5.1419804 | R12: 5.1419804 | S12: 5.1419804 | T12: 5.1419804
N13: Oxygen consumption, kg/s | O13: - | P13: 8.4990979 | Q13: 8.4990979 | R13: 8.4990979 | S13: 8.4990979 | T13: 8.4990979
A14: Cement plant 1800 tpd of clinker production - 0,51 MtCO2/y | N14: MEA reb duty, MW | O14: - | P14: 0 | Q14: 7.2054566 | R14: 12.009094 | S14: 19.214551 | T14: 24.018189
A15: CAPEX [M€] | C15: CO2 removal rate (direct emissions) | N15: MEA reb duty, MJ/kgCO2 | O15: - | P15: 0 | Q15: 3.5409355 | R15: 3.5409355 | S15: 3.5409355 | T15: 3.5409355
C16: P.Oxy only | D16: MEA 30% - 95%CCR | E16: MEA 50% - 95%CCR | F16: MEA 80% - 95%CCR | G16: MEA 100% - 95%CCR | N16: ASU electric power, MW | O16: - | P16: 7.0372531 | Q16: 7.0372531 | R16: 7.0372531 | S16: 7.0372531 | T16: 7.0372531
C17: 50.76 | D17: 64.722332 | E17: 68.472346 | F17: 73.261252 | G17: 76.12 | N17: CO2 recycle fan power, MW | O17: - | P17: 0.16516842 | Q17: 0.16516842 | R17: 0.16516842 | S17: 0.16516842 | T17: 0.16516842
N18: MEA specific electric power consumption, kWh/tCO2 | O18: - | P18: - | Q18: 38.587339 | R18: 38.587339 | S18: 38.587339 | T18: 38.587339
B19: MEA capacity t/h CO2 out | C19: 0 | D19: =Q36*3600/1000 -> 4.4302473 | E19: =R36*3600/1000 -> 7.3837455 | F19: =S36*3600/1000 -> 11.813993 | G19: =T36*3600/1000 -> 14.767491 | N19: MEA electric power consumption, MW | O19: - | P19: - | Q19: 0.28267722 | R19: 0.4711287 | S19: 0.75380593 | T19: 0.94225741
B20: CAPEX in EUR | D20: =(D17-$C$17)*10^6 -> 13962332 | E20: =(E17-$C$17)*10^6 -> 17712346 | F20: =(F17-$C$17)*10^6 -> 22501252 | G20: =(G17-$C$17)*10^6 -> 25360000 | N20: Net electricity production from steam cycle, MWe | O20: - | P20: 9.78 | Q20: - | R20: - | S20: - | T20: -
B21: specific capex eur/(t_out/h) | D21: =D20/D19 -> 3151592 | E21: =E20/E19 -> 2398829.4 | F21: =F20/F19 -> 1904627.2 | G21: =G20/G19 -> 1717285.6 | N21: Thermal Power available for recovery, kW | O21: - | P21: 34915.217 | Q21: 34915.217 | R21: 34915.217 | S21: 34915.217 | T21: 34915.217
B22: specific capex Meur/(t_out/h) | D22: =D21/10^6 -> 3.151592 | E22: =E21/10^6 -> 2.3988294 | F22: =F21/10^6 -> 1.9046272 | G22: =G21/10^6 -> 1.7172856 | N22: Net th. Power consumtpion MEA, MW | O22: - | P22: 0 | Q22: -27.709761 | R22: -22.906123 | S22: -15.700666 | T22: -10.897028
B23: fixed OPEX Meur | C23: 9.31 | D23: 9.67 | E23: 9.75 | F23: 9.89 | G23: 9.98 | N23: Net electricity production from steam cycle, MWe | P23: 9.78 | Q23: 0 | R23: 0 | S23: 0 | T23: 0
B24: fixed OPEX MEA Meur | C24: =C23-$C$23 -> 0 | D24: =D23-$C$23 -> 0.36 | E24: =E23-$C$23 -> 0.44 | F24: =F23-$C$23 -> 0.58 | G24: =G23-$C$23 -> 0.67 | N24: ∆th. Power cons., MJ/kgCO2 | O24: 0 | P24: 1.1132667 | Q24: 1.0311119 | R24: 0.98276256 | S24: 0.91818156 | T24: 0.87964505
B25: fixed OPEX Fraction of capex | C25: =C10/C4 -> 0.16447823 | D25: =D24*10^6/D20 -> 0.025783659 | E25: =E24*10^6/E20 -> 0.02484143 | F25: =F24*10^6/F20 -> 0.025776344 | G25: =G24*10^6/G20 -> 0.026419558 | N25: Electricity cons, KW (ASU+CO2recyfan+MEA pumps/fans) | O25: 0 | P25: -2577.5785 | Q25: 7202.7042 | R25: 7202.8926 | S25: 7203.1753 | T25: 7203.3638
N26: ∆el. Power cons., kWh/tCO2 | O26: 0 | P26: -28.034494 | Q26: 72.557617 | R26: 69.157162 | S26: 64.615122 | T26: 61.904815
N27: Clinker emis. factor, kgCO2/tCLK | O27: 859.37856 | P27: 205.23662 | Q27: 146.62987 | R27: 107.5587 | S27: 48.951955 | T27: 9.8807885
N28: Sp. Fuel consumption, MJ/tCLK | O28: 3201.756 | P28: 4020.7253 | Q28: 4020.7253 | R28: 4020.7253 | S28: 4020.7253 | T28: 4020.7253
O30: CEMCAP ref. plant 1800 tpd of clinker production - 0,51 MtCO2/y - high CO2
O31: No CCS | P31: P.Oxy only | Q31: MEA 30% - 95%CCR | R31: MEA 50% - 95%CCR | S31: MEA 80% - 95%CCR | T31: MEA 100% - 95%CCR
N32: Clinker production, tpd | O32: 1800.176 | P32: 1799.9672 | Q32: 1799.9672 | R32: 1799.9672 | S32: 1799.9672 | T32: 1799.9672
N33: CO2 basic cement plant, kg/s | O33: 17.921466 | P33: - | Q33: - | R33: - | S33: - | T33: -
N34: CO2 p.oxy cement plant, kg/s | O34: - | P34: 19.661165 | Q34: 19.661165 | R34: 19.661165 | S34: 19.661165 | T34: 19.661165
N35: CO2 emission | O35: 17.921466 | P35: 4.3097686 | Q35: 3.0791444 | R35: 2.2587282 | S35: 1.028104 | T35: 0.20768782
N36: CO2 capture by MEA, kg/s | O36: - | P36: 0 | Q36: 1.2306242 | R36: 2.0510404 | S36: 3.2816647 | T36: 4.1020808
N37: Total CO2 captured, kg/s | O37: - | P37: 15.351396 | Q37: 16.582021 | R37: 17.402437 | S37: 18.633061 | T37: 19.453477
A38: electricity_recovery_oxy | B38: MWh/t_co2_out | C38: =P20/(P8*3600/1000) -> 0.10637013 | N38: Direct CO2 avoided, kg/s | O38: 0 | P38: 13.611697 | Q38: 14.842322 | R38: 15.662738 | S38: 16.893362 | T38: 17.713778
A39: thermal_consumption_oxy | B39: MWh/t_co2_out | C39: =AVERAGE(P53,P24)*1000/3600 -> 0.31280885 | N39: Actual direct CO2 avoided, kg/s | O39: - | P39: 11.871998 | Q39: 13.102623 | R39: 13.923039 | S39: 15.153663 | T39: 15.974079
A40: electric_consumption_oxy | B40: MWh/t_co2_out | C40: =(P16+P17)/(P8*3600/1000) -> 0.078335633 | N40: CO2 avoidance rate (direct emission) | O40: 0 | P40: 0.75951919 | Q40: 0.8281868 | R40: 0.87396521 | S40: 0.94263282 | T40: 0.98841123
A41: electric_consumption_mea | B41: MWh/t_co2_out | C41: =Q18/1000 -> 0.038587339 | N41: kgfuel/s | O41: 2.4618331 | P41: 3.1058323 | Q41: 3.1058323 | R41: 3.1058323 | S41: 3.1058323 | T41: 3.1058323
...
